<?xml version="1.0" ?>
<sdf version="1.6">
  <model name='Dolly'>

    <link name="base_footprint"/>

    <pose>0 0 0.225 0 -0 0</pose>

    <link name='base_link'>
      <inertial>
        <mass>1.0</mass>
        <inertia>
          <ixx>0.0227</ixx>
          <ixy>0</ixy>
          <ixz>0</ixz>
          <iyy>0.0852</iyy>
          <iyz>0</iyz>
          <izz>0.1041</izz>
        </inertia>
      </inertial>
      <visual name='visual'>
        <geometry>
          <box>
            <size>1.0 0.5 0.15</size>
          </box>
        </geometry>
      </visual>
      <collision name="base_link_collision">
        <pose>0 0 0 0 0 0</pose>
        <geometry>
          <box>
            <size>1.0 0.5 0.15</size>
          </box>
        </geometry>
      </collision>
      </link>

    <link name="base_scan">
      <inertial>
        <pose>0.00 0 0.15 0 0 0</pose>
        <inertia>
          <ixx>0.001</ixx>
          <ixy>0.000</ixy>
          <ixz>0.000</ixz>
          <iyy>0.001</iyy>
          <iyz>0.000</iyz>
          <izz>0.001</izz>
        </inertia>
        <mass>0.125</mass>
      </inertial>
      <collision name="lidar_sensor_collision">
        <pose>0.0 0 0.15 0 0 0</pose>
        <geometry>
          <cylinder>
            <radius>0.0508</radius>
            <length>0.055</length>
          </cylinder>
        </geometry>
      </collision>

      <visual name="lidar_sensor_visual">
        <pose>0.0 0 0.15 0 0 0</pose>
        <geometry>
          <mesh>
            <uri>model://dolly/meshes/lds.dae</uri>
            <scale>0.001 0.001 0.001</scale>
          </mesh>
        </geometry>
      </visual>
      <sensor name="sensor_ray" type="ray">
        <pose>0.0 0 0.2 0 0 0</pose>
        <ray>
          <scan>
            <horizontal>
              <samples>360</samples>
              <resolution>1.0</resolution>
              <min_angle>0.0</min_angle>
              <max_angle>6.280000</max_angle>
            </horizontal>
          </scan>
          <range>
            <min>0.120000</min>
            <max>3.5</max>
          </range>
          <noise>
            <type>gaussian</type>
            <mean>0.0</mean>
            <stddev>0.01</stddev>
          </noise>
        </ray>
        <always_on>true</always_on>
        <visualize>false</visualize>
        <topic>scan</topic>

        <update_rate>100.0</update_rate>
        <plugin name="laser" filename="libgazebo_ros_ray_sensor.so">
          <ros>
          <!--
            <namespace>/dolly</namespace>
          -->
            <remapping>~/out:=scan</remapping>
          </ros>
          <output_type>sensor_msgs/LaserScan</output_type>
          <frame_name>base_scan</frame_name>
        </plugin>
      </sensor>
    </link>
      
    <link name='caster'>
      <pose>-0.3 0 -0.125 0 0 0</pose>
      <inertial>
        <mass>0.0415553</mass>
        <inertia>
          <ixx>7.97741e-05</ixx>
          <ixy>0</ixy>
          <ixz>0</ixz>
          <iyy>7.97741e-05</iyy>
          <iyz>0</iyz>
          <izz>7.97741e-05</izz>
        </inertia>
      </inertial>
      <visual name='visual'>
        <geometry>
          <sphere>
            <radius>0.1</radius>
          </sphere>
        </geometry>
        <material>
          <diffuse>0.5 0.5 0.5 1</diffuse>
          <ambient>0 0 0 1</ambient>
          <specular>1 1 1 1</specular>
          <emissive>0 0 0 1</emissive>
        </material>
      </visual>
      <collision name='collision'>
        <geometry>
          <sphere>
            <radius>0.1</radius>
          </sphere>
        </geometry>
        <surface>
          <friction>
            <ode>
              <mu>1</mu>
              <mu2>1</mu2>
              <slip1>0</slip1>
              <slip2>0</slip2>
            </ode>
          </friction>
          <contact>
            <ode>
              <soft_cfm>0</soft_cfm>
              <soft_erp>0.2</soft_erp>
              <kp>1e+13</kp>
              <kd>1</kd>
              <max_vel>0.01</max_vel>
              <min_depth>0</min_depth>
            </ode>
          </contact>
        </surface>
      </collision>
    </link>


    <link name='caster_front'>
      <pose>0.3 0 -0.125 0 0 0</pose>
      <inertial>
        <mass>0.0415553</mass>
        <inertia>
          <ixx>7.97741e-05</ixx>
          <ixy>0</ixy>
          <ixz>0</ixz>
          <iyy>7.97741e-05</iyy>
          <iyz>0</iyz>
          <izz>7.97741e-05</izz>
        </inertia>
      </inertial>
      <visual name='visual'>
        <geometry>
          <sphere>
            <radius>0.1</radius>
          </sphere>
        </geometry>
        <material>
          <diffuse>0.5 0.5 0.5 1</diffuse>
          <ambient>0 0 0 1</ambient>
          <specular>1 1 1 1</specular>
          <emissive>0 0 0 1</emissive>
        </material>
      </visual>
      <collision name='collision'>
        <geometry>
          <sphere>
            <radius>0.1</radius>
          </sphere>
        </geometry>
        <surface>
          <friction>
            <ode>
              <mu>1</mu>
              <mu2>1</mu2>
              <slip1>0</slip1>
              <slip2>0</slip2>
            </ode>
          </friction>
          <contact>
            <ode>
              <soft_cfm>0</soft_cfm>
              <soft_erp>0.2</soft_erp>
              <kp>1e+13</kp>
              <kd>1</kd>
              <max_vel>0.01</max_vel>
              <min_depth>0</min_depth>
            </ode>
          </contact>
        </surface>
      </collision>
    </link>

    <link name='left_wheel'>
      <pose>0.0 0.3 -0.075 -1.5707 0 0</pose>
      <inertial>
        <mass>0.5</mass>
        <inertia>
          <ixx>0.0029</ixx>
          <ixy>0</ixy>
          <ixz>0</ixz>
          <iyy>0.0029</iyy>
          <iyz>0</iyz>
          <izz>0.0056</izz>
        </inertia>
      </inertial>
      <visual name='visual'>
        <geometry>
          <cylinder>
            <radius>0.15</radius>
            <length>0.05</length>
          </cylinder>
        </geometry>
        <material>
          <diffuse>0.5 0.5 0.5 1</diffuse>
          <ambient>0 0 0 1</ambient>
          <specular>1 1 1 1</specular>
          <emissive>0 0 0 1</emissive>
        </material>
      </visual>
      <collision name='collision'>
        <geometry>
          <sphere>
            <radius>0.15</radius>
          </sphere>
        </geometry>
        <surface>
          <friction>
            <ode>
              <mu>1</mu>
              <mu2>1</mu2>
              <slip1>0</slip1>
              <slip2>0</slip2>
            </ode>
          </friction>
          <contact>
            <ode>
              <soft_cfm>0</soft_cfm>
              <soft_erp>0.2</soft_erp>
              <kp>1e+13</kp>
              <kd>1</kd>
              <max_vel>0.01</max_vel>
              <min_depth>0.01</min_depth>
            </ode>
          </contact>
        </surface>
      </collision>
    </link>

    <link name='right_wheel'>
      <pose>0.0 -0.3 -0.075 -1.5707 0 0</pose>
      <inertial>
        <mass>0.5</mass>
        <inertia>
          <ixx>0.0029</ixx>
          <ixy>0</ixy>
          <ixz>0</ixz>
          <iyy>0.0029</iyy>
          <iyz>0</iyz>
          <izz>0.0056</izz>
        </inertia>
      </inertial>
      <visual name='visual'>
        <geometry>
          <cylinder>
            <radius>0.15</radius>
            <length>0.05</length>
          </cylinder>
        </geometry>
        <material>
          <diffuse>0.5 0.5 0.5 1</diffuse>
          <ambient>0 0 0 1</ambient>
          <specular>1 1 1 1</specular>
          <emissive>0 0 0 1</emissive>
        </material>
      </visual>
      <collision name='collision'>
        <geometry>
          <sphere>
            <radius>0.15</radius>
          </sphere>
        </geometry>
        <surface>
          <friction>
            <ode>
              <mu>1</mu>
              <mu2>1</mu2>
              <slip1>0</slip1>
              <slip2>0</slip2>
            </ode>
          </friction>
          <contact>
            <ode>
              <soft_cfm>0</soft_cfm>
              <soft_erp>0.2</soft_erp>
              <kp>1e+13</kp>
              <kd>1</kd>
              <max_vel>0.01</max_vel>
              <min_depth>0.01</min_depth>
            </ode>
          </contact>
        </surface>
      </collision>
    </link>
 


    <joint name="base_joint" type="fixed">
      <parent>base_footprint</parent>
      <child>base_link</child>
      <pose>0.0 0.0 0.010 0 0 0</pose>
    </joint>


    <joint name="lidar_joint" type="fixed">
      <parent>base_link</parent>
      <child>base_scan</child>
      <pose>-0.032 0 0.15 0 0 0</pose>
      <axis>
        <xyz>0 0 1</xyz>
      </axis>
  
    </joint>


    <joint name='left_wheel_joint' type='revolute'>
      <parent>base_link</parent>
      <child>left_wheel</child>
      <axis>
        <xyz>0 0 1</xyz>
        <limit>
          <lower>-1.79769e+308</lower>
          <upper>1.79769e+308</upper>
        </limit>
      </axis>
    </joint>

    <joint name='right_wheel_joint' type='revolute'>
      <parent>base_link</parent>
      <child>right_wheel</child>
      <axis>
        <xyz>0 0 1</xyz>
        <limit>
          <lower>-1.79769e+308</lower>
          <upper>1.79769e+308</upper>
        </limit>
      </axis>
    </joint>

    <joint name='caster_wheel' type='ball'>
      <parent>base_link</parent>
      <child>caster</child>
    </joint>

    <joint name='caster_front_wheel' type='ball'>
      <parent>base_link</parent>
      <child>caster_front</child>
    </joint>


    <plugin name='diff_drive' filename='libgazebo_ros_diff_drive.so'>

      <!--
      <ros>
        <namespace>/dolly</namespace>
      </ros>
      -->


      <!-- wheels -->
      <left_joint>left_wheel_joint</left_joint>
      <right_joint>right_wheel_joint</right_joint>

      <!-- kinematics -->
      <wheel_separation>1.25</wheel_separation>
      <wheel_diameter>0.3</wheel_diameter>

      <!-- limits -->
      <max_wheel_torque>20</max_wheel_torque>
      <max_wheel_acceleration>1.0</max_wheel_acceleration>

      <!-- output -->
      <publish_odom>true</publish_odom>
      <publish_odom_tf>true</publish_odom_tf>
      <publish_wheel_tf>true</publish_wheel_tf>
      
      
      <odometry_frame>odom</odometry_frame>
      <robot_base_frame>base_footprint</robot_base_frame>
      <command_topic>cmd_vel</command_topic>

    </plugin>

    <plugin name="dolly_joint_state" filename="libgazebo_ros_joint_state_publisher.so">
      <ros>
        <!-- <namespace>/tb3</namespace> -->
        <remapping>~/out:=joint_states</remapping>
      </ros>
      <update_rate>30</update_rate>
      <joint_name>left_wheel_joint</joint_name>
      <joint_name>right_wheel_joint</joint_name>
    </plugin>      

  </model>
</sdf>
